Traceback (most recent call last):
  File "D:/Python/Section 12 - Debugging/the_raise_and_assert_statements.py", line 42, in <module>
    raise Exception('This is the error message')
Exception: This is the error message
Traceback (most recent call last):
  File "D:/Python/Section 12 - Debugging/the_raise_and_assert_statements.py", line 42, in <module>
    raise Exception('This is the error message')
Exception: This is the error message
Traceback (most recent call last):
  File "D:/Python/Section 12 - Debugging/the_raise_and_assert_statements.py", line 42, in <module>
    raise Exception('This is the error message')
Exception: This is the error message
Traceback (most recent call last):
  File "D:/Python/Section 12 - Debugging/the_raise_and_assert_statements.py", line 42, in <module>
    raise Exception('This is the error message')
Exception: This is the error message
Traceback (most recent call last):
  File "D:/Python/Section 12 - Debugging/the_raise_and_assert_statements.py", line 42, in <module>
    raise Exception('This is the error message')
Exception: This is the error message
Traceback (most recent call last):
  File "D:/Python/Section 12 - Debugging/the_raise_and_assert_statements.py", line 42, in <module>
    raise Exception('This is the error message')
Exception: This is the error message
